Workbook

Sheet Start
A1: WürfelWächter · Der Bund der Geschichten (Parallel-Version)
A2: Zweites Deck auf denselben Vorgaben · komplett neue Echt-Karten-Zuordnung · Commander (100) · Stand 07.09.2026
A5: KARTEN GESAMT | D5: LÄNDER | G5: STANDARDLÄNDER | J5: COMMANDER
A6: =SUM(Deckliste!$E$5:$E$104) | D6: =SUMIF(Deckliste!$F$5:$F$104,"Standardland",Deckliste!$E$5:$E$104)+SUMIF(Deckliste!$F$5:$F$104,"Nichtstandardland",Deckliste!$E$5:$E$104) | G6: =SUMIF(Deckliste!$F$5:$F$104,"Standardland",Deckliste!$E$5:$E$104) | J6: =SUMIF(Deckliste!$D$5:$D$104,"Commander",Deckliste!$E$5:$E$104)
A10: Commander | B10: Esika, God of the Tree // The Prismatic Bridge → WürfelWächter · Wächter am Portal aller Geschichten
A11: Idee | B11: Dieselben Vorgaben wie im Original, aber jede Figur, jeder Insider und jedes Land trägt eine ANDERE reale MTG-Karte. Der WürfelWächter (Esika // The Prismatic Bridge) hält Wache am Portal, aus dem jeden Zug ein Held aller Kampagnen tritt.
A13: So liest du die Datei
A14: Deckliste | B14: Alle 100 physischen Karten; echte Karte und WürfelWächter-Design nebeneinander, mit Deck-Funktion und Begründung.
A15: Designs | B15: Konkretes Bildbriefing, Flavor-Vorschlag, bewusste Adaption und Regelgrenze je Karte.
A16: Bildpaare | B16: Heruntergeladene echte Kartenbilder plus vorhandene WürfelWächter-Webreferenz (Porträt/Kampagne).
A17: Kartendaten | B17: Unveränderte englische Oracle-Texte und geprüfte Papierdrucke (Scryfall, Stichtag 07.09.2026).
A18: Spielplan | B18: Mulligan, Manabasis, Siegplan, Esika-Interaktionen und ein verbindlicher Gestaltungsrahmen.
A19: Auswahlabgleich / Token | B19: Nachweis: jeder Charakter und jeder Insider mit eigener Karte, jeder Spieler mindestens erwähnt. Plus Hilfskarten außerhalb der 100.
A21: Abdeckung (Vorgaben zuerst) | B21: 1 Commander + 27 Charaktere (Karten 2–28) + ALLE 23 Insider (u. a. 43–56, 90–100) + 15 Kampagnen-Basics. Spieler bekommen KEINE eigene Karte, werden aber alle erwähnt (11 über ihren Charakter; Questen & Quatschen, Dwarfmasters, Chrys Mats, Josh und Nils gemeinsam über die Sammelkarte „Gastauftritte“, #041). Erst danach aufgefüllt.
A22: Was neu ist ggü. der letzten Fassung | B22: Keine dedizierten Spieler-Karten mehr. Nils, Dwarfmasters und Questen & Quatschen sind mit den Gästen Chrys Mats (Synchronsprecher) und Josh (Spieleabend) auf einer Karte „Gastauftritte“ (#041) zusammengefasst. Die frei gewordenen Slots sind stärker mit WürfelWächter-Themen verzahnt: „Ich weiß …“ (Mystic Remora), „Stumpf ist Trumpf.“ (Rancor), „Ja, sag ich ja.“ (Bloom Tender), Der lange Kampagnenweg (Kodama's Reach), WürfelWissen (Rhystic Study), Sardior (Balefire Dragon), Das Logbuch des Bundes (Garruk's Uprising), Octo’Talis rückt vor (Cathars' Crusade), Moss Mane (Seedborn Muse), Der Essenzträger-Kern (Wayfarer's Bauble). „Studiolampe des ArtandTech.space“ ist jetzt schlicht „WürfelWächter Studio“; „Das Siegel der drei Streamabende“ heißt „Streamingplan“; Farewell ist „Der große Meister“; Lightning Greaves nicht mehr Nebelhauer.
A23: Bewusst wiederholt | B23: Echte Format-Staples ohne sinnvolle Alternative: Sol Ring, Command Tower.
A25: Regelbindung | B25: Kartennamen, Manakosten, Typzeilen, Legendärstatus und Oracle-Texte der echten Karten bleiben unverändert. Die WürfelWächter-Ebene ist Name, Bild und Flavor – niemals neuer Regeltext.
A26: Quellenstand | B26: Kartendaten: Scryfall API. Regeln: offizielle Commander-Regeln. Website-Referenzen: wuerfelwaechter.de / octocon.wuerfelwaechter.de.

Sheet Deckliste
A1: 100 Karten · echte Karte und WürfelWächter-Design nebeneinander
A2: Jede Zeile ist eine physische Karte. Auch alle 15 Standardländer sind einzeln aufgeführt.
A4: Nr. | B4: Echte MTG-Karte | C4: WürfelWächter-Design | D4: Zone | E4: Anzahl | F4: Haupttyp | G4: Manakosten | H4: Manawert | I4: Funktion im Deck | J4: Kampagne / Bezug | K4: Warum die echte Karte passt | L4: Prüfung | M4: Kartenquelle | N4: WürfelWächter-Quelle | O4: Original-Typzeile | P4: Legendär?
A5: 1 | B5: Esika, God of the Tree | C5: WürfelWächter · Wächter am Portal aller Geschichten | D5: Commander | E5: 1 | F5: =IFERROR(VLOOKUP(B5,Kartendaten!$A$5:$U$94,5,FALSE),"UNBEKANNT") | G5: =IFERROR(VLOOKUP(B5,Kartendaten!$A$5:$U$94,2,FALSE),"UNBEKANNT") | H5: =IFERROR(VLOOKUP(B5,Kartendaten!$A$5:$U$94,3,FALSE),"UNBEKANNT") | I5: Commander; verwandelt den Heldenbund in Manaquelle mit Wachsamkeit; Rückseite holt jeden Zug einen Helden ins Spiel | J5: WürfelWächter · Maskottchen / Commander | K5: Esika macht aus jeder legendären Kreatur eine wachsame Manaquelle – der Bund, der gemeinsam Wache hält und trotzdem angreift. Die Rückseite, das fünffarbige Portal, holt jeden Zug einen Helden aus dem Logbuch an den Tisch: genau das Bild des WürfelWächter-Maskottchens als Hüter aller Geschichten. | L5: =IFERROR(IF(AND(VLOOKUP(B5,Kartendaten!$A$5:$U$94,6,FALSE)="legal",VLOOKUP(B5,Kartendaten!$A$5:$U$94,19,FALSE)="Nein",VLOOKUP(B5,Kartendaten!$A$5:$U$94,20,FALSE)="Ja",VLOOKUP(B5,Kartendaten!$A$5:$U$94,21,FALSE)="Ja",OR(F5="Standardland",SUMIF($B$5:$B$104,B5,$E$5:$E$104)=1)),"OK","PRÜFEN"),"PRÜFEN") | M5: https://scryfall.com/card/khm/168/esika-god-of-the-tree-the-prismatic-bridge?utm_source=api | N5: https://wuerfelwaechter.de/ | O5: =IFERROR(VLOOKUP(B5,Kartendaten!$A$5:$U$94,4,FALSE),"UNBEKANNT") | P5: =IF(ISNUMBER(SEARCH("Legendary",O5)),"Ja","Nein")
A6: 2 | B6: Aurelia, the Warleader | C6: Jonvus Sonnenzorn-ChewChew, führt den Bund | D6: Bibliothek | E6: 1 | F6: =IFERROR(VLOOKUP(B6,Kartendaten!$A$5:$U$94,5,FALSE),"UNBEKANNT") | G6: =IFERROR(VLOOKUP(B6,Kartendaten!$A$5:$U$94,2,FALSE),"UNBEKANNT") | H6: =IFERROR(VLOOKUP(B6,Kartendaten!$A$5:$U$94,3,FALSE),"UNBEKANNT") | I6: Fliegender Anführer mit Wachsamkeit und Eile; zusätzliche Kampfphase, wenn Octo’Talis vorrückt | J6: Die Legende des Rubindrachen · Jonas | K6: Jonvus ist der Paladin, der Octo’Talis in den Kampf gegen das Ende der Welt führt. Aurelia gibt dem Bund Eile, Wachsamkeit und eine zweite Kampfphase – ein echter Anführerkörper statt eines schmalen 2/2. Rot-Weiß passt exakt: Rubindrachen-Rot und Paladin-Weiß. | L6: =IFERROR(IF(AND(VLOOKUP(B6,Kartendaten!$A$5:$U$94,6,FALSE)="legal",VLOOKUP(B6,Kartendaten!$A$5:$U$94,19,FALSE)="Nein",VLOOKUP(B6,Kartendaten!$A$5:$U$94,20,FALSE)="Ja",VLOOKUP(B6,Kartendaten!$A$5:$U$94,21,FALSE)="Ja",OR(F6="Standardland",SUMIF($B$5:$B$104,B6,$E$5:$E$104)=1)),"OK","PRÜFEN"),"PRÜFEN") | M6: https://scryfall.com/card/fdn/651/aurelia-the-warleader?utm_source=api | N6: https://wuerfelwaechter.de/Charakter/Details/21 | O6: =IFERROR(VLOOKUP(B6,Kartendaten!$A$5:$U$94,4,FALSE),"UNBEKANNT") | P6: =IF(ISNUMBER(SEARCH("Legendary",O6)),"Ja","Nein")
A7: 3 | B7: Selvala, Explorer Returned | C7: Vorian Flammenzorn, zurück unter Sternen | D7: Bibliothek | E7: 1 | F7: =IFERROR(VLOOKUP(B7,Kartendaten!$A$5:$U$94,5,FALSE),"UNBEKANNT") | G7: =IFERROR(VLOOKUP(B7,Kartendaten!$A$5:$U$94,2,FALSE),"UNBEKANNT") | H7: =IFERROR(VLOOKUP(B7,Kartendaten!$A$5:$U$94,3,FALSE),"UNBEKANNT") | I7: Manaaufbau und Kartenvorteil für den ganzen Tisch | J7: Die Legende des Rubindrachen · Kevin | K7: Eine elfische Kundschafterin, die aus dem ‚Dienst‘ zurückkehrt und dem ganzen Tisch Mana und Karten bringt – Vorians Weg aus dem Schatten Asmodeus’ hin zu Ausgleich und Fürsorge. | L7: =IFERROR(IF(AND(VLOOKUP(B7,Kartendaten!$A$5:$U$94,6,FALSE)="legal",VLOOKUP(B7,Kartendaten!$A$5:$U$94,19,FALSE)="Nein",VLOOKUP(B7,Kartendaten!$A$5:$U$94,20,FALSE)="Ja",VLOOKUP(B7,Kartendaten!$A$5:$U$94,21,FALSE)="Ja",OR(F7="Standardland",SUMIF($B$5:$B$104,B7,$E$5:$E$104)=1)),"OK","PRÜFEN"),"PRÜFEN") | M7: https://scryfall.com/card/mkc/218/selvala-explorer-returned?utm_source=api | N7: https://wuerfelwaechter.de/Charakter/Details/58 | O7: =IFERROR(VLOOKUP(B7,Kartendaten!$A$5:$U$94,4,FALSE),"UNBEKANNT") | P7: =IF(ISNUMBER(SEARCH("Legendary",O7)),"Ja","Nein")
A8: 4 | B8: Myrel, Shield of Argive | C8: Hemish, Bannerträger Octo’Talis’ | D8: Bibliothek | E8: 1 | F8: =IFERROR(VLOOKUP(B8,Kartendaten!$A$5:$U$94,5,FALSE),"UNBEKANNT") | G8: =IFERROR(VLOOKUP(B8,Kartendaten!$A$5:$U$94,2,FALSE),"UNBEKANNT") | H8: =IFERROR(VLOOKUP(B8,Kartendaten!$A$5:$U$94,3,FALSE),"UNBEKANNT") | I8: Spielstein-Anthem im Kampf; sperrt gegnerische Reaktionen im eigenen Zug | J8: Die Legende des Rubindrachen · Jan | K8: Myrel stellt im Kampf Soldaten auf und sperrt gegnerische Zwischenzüge – ein Bannerträger, der Octo’Talis rallyt und beschützt. | L8: =IFERROR(IF(AND(VLOOKUP(B8,Kartendaten!$A$5:$U$94,6,FALSE)="legal",VLOOKUP(B8,Kartendaten!$A$5:$U$94,19,FALSE)="Nein",VLOOKUP(B8,Kartendaten!$A$5:$U$94,20,FALSE)="Ja",VLOOKUP(B8,Kartendaten!$A$5:$U$94,21,FALSE)="Ja",OR(F8="Standardland",SUMIF($B$5:$B$104,B8,$E$5:$E$104)=1)),"OK","PRÜFEN"),"PRÜFEN") | M8: https://scryfall.com/card/bro/18/myrel-shield-of-argive?utm_source=api | N8: https://wuerfelwaechter.de/Charakter/Details/36 | O8: =IFERROR(VLOOKUP(B8,Kartendaten!$A$5:$U$94,4,FALSE),"UNBEKANNT") | P8: =IF(ISNUMBER(SEARCH("Legendary",O8)),"Ja","Nein")
A9: 5 | B9: Ranar the Ever-Watchful | C9: Susi Lichtschwur, mit leichtem Schritt | D9: Bibliothek | E9: 1 | F9: =IFERROR(VLOOKUP(B9,Kartendaten!$A$5:$U$94,5,FALSE),"UNBEKANNT") | G9: =IFERROR(VLOOKUP(B9,Kartendaten!$A$5:$U$94,2,FALSE),"UNBEKANNT") | H9: =IFERROR(VLOOKUP(B9,Kartendaten!$A$5:$U$94,3,FALSE),"UNBEKANNT") | I9: Blink/Exil-Versteck; Geist-Spielsteine; Kartenauswahl beim Ausblenden | J9: Die Legende des Rubindrachen · Janna | K9: Ranar blendet Karten aus, blinkt Kreaturen und macht Geist-Spielsteine: Susis leichter Schritt, mit dem sie unbemerkt an Wachen und Zauberbüchern vorbeikommt. | L9: =IFERROR(IF(AND(VLOOKUP(B9,Kartendaten!$A$5:$U$94,6,FALSE)="legal",VLOOKUP(B9,Kartendaten!$A$5:$U$94,19,FALSE)="Nein",VLOOKUP(B9,Kartendaten!$A$5:$U$94,20,FALSE)="Ja",VLOOKUP(B9,Kartendaten!$A$5:$U$94,21,FALSE)="Ja",OR(F9="Standardland",SUMIF($B$5:$B$104,B9,$E$5:$E$104)=1)),"OK","PRÜFEN"),"PRÜFEN") | M9: https://scryfall.com/card/khc/2/ranar-the-ever-watchful?utm_source=api | N9: https://wuerfelwaechter.de/Charakter/Details/70 | O9: =IFERROR(VLOOKUP(B9,Kartendaten!$A$5:$U$94,4,FALSE),"UNBEKANNT") | P9: =IF(ISNUMBER(SEARCH("Legendary",O9)),"Ja","Nein")
A10: 6 | B10: Arahbo, Roar of the World | C10: Damon Driftwood, Stärke schützt | D10: Bibliothek | E10: 1 | F10: =IFERROR(VLOOKUP(B10,Kartendaten!$A$5:$U$94,5,FALSE),"UNBEKANNT") | G10: =IFERROR(VLOOKUP(B10,Kartendaten!$A$5:$U$94,2,FALSE),"UNBEKANNT") | H10: =IFERROR(VLOOKUP(B10,Kartendaten!$A$5:$U$94,3,FALSE),"UNBEKANNT") | I10: Kampf-Boost; hebt in jedem Kampf eine Kreatur (Cleemoe) hervor | J10: Icewind Dale – Rime of the Frostmaiden · Jonas | K10: Arahbo hebt in jedem Kampf eine Kreatur hervor und schützt sie – Damon, der seine Ziehtochter Cleemoe mit einem löwenhaften Schild deckt. ‚Stärke schützt.‘ | L10: =IFERROR(IF(AND(VLOOKUP(B10,Kartendaten!$A$5:$U$94,6,FALSE)="legal",VLOOKUP(B10,Kartendaten!$A$5:$U$94,19,FALSE)="Nein",VLOOKUP(B10,Kartendaten!$A$5:$U$94,20,FALSE)="Ja",VLOOKUP(B10,Kartendaten!$A$5:$U$94,21,FALSE)="Ja",OR(F10="Standardland",SUMIF($B$5:$B$104,B10,$E$5:$E$104)=1)),"OK","PRÜFEN"),"PRÜFEN") | M10: https://scryfall.com/card/c17/35/arahbo-roar-of-the-world?utm_source=api | N10: https://wuerfelwaechter.de/Charakter/Details/28 | O10: =IFERROR(VLOOKUP(B10,Kartendaten!$A$5:$U$94,4,FALSE),"UNBEKANNT") | P10: =IF(ISNUMBER(SEARCH("Legendary",O10)),"Ja","Nein")
A11: 7 | B11: Kardur, Doomscourge | C11: Mumpfi Nebelhauer, Schuldner der Phaerimm | D11: Bibliothek | E11: 1 | F11: =IFERROR(VLOOKUP(B11,Kartendaten!$A$5:$U$94,5,FALSE),"UNBEKANNT") | G11: =IFERROR(VLOOKUP(B11,Kartendaten!$A$5:$U$94,2,FALSE),"UNBEKANNT") | H11: =IFERROR(VLOOKUP(B11,Kartendaten!$A$5:$U$94,3,FALSE),"UNBEKANNT") | I11: 4/3-Körper; beim Eintritt Opferzwang für jeden Gegner; treibt die Gegner gegeneinander | J11: Icewind Dale – Rime of the Frostmaiden · Jonas | K11: Nebelhauer verrät im Kampagnenverlauf seine Gefährten für die Macht der Phaerimm. Kardur zwingt Gegner zum Opfer und stiftet Unfrieden zwischen ihnen – ein echter 4/3-Körper und das Verrat-/Zwietracht-Motiv statt eines schmalen 1/3. | L11: =IFERROR(IF(AND(VLOOKUP(B11,Kartendaten!$A$5:$U$94,6,FALSE)="legal",VLOOKUP(B11,Kartendaten!$A$5:$U$94,19,FALSE)="Nein",VLOOKUP(B11,Kartendaten!$A$5:$U$94,20,FALSE)="Ja",VLOOKUP(B11,Kartendaten!$A$5:$U$94,21,FALSE)="Ja",OR(F11="Standardland",SUMIF($B$5:$B$104,B11,$E$5:$E$104)=1)),"OK","PRÜFEN"),"PRÜFEN") | M11: https://scryfall.com/card/dsc/223/kardur-doomscourge?utm_source=api | N11: https://wuerfelwaechter.de/Charakter/Details/29 | O11: =IFERROR(VLOOKUP(B11,Kartendaten!$A$5:$U$94,4,FALSE),"UNBEKANNT") | P11: =IF(ISNUMBER(SEARCH("Legendary",O11)),"Ja","Nein")
A12: 8 | B12: Giada, Font of Hope | C12: Cleemoe Driftwood, Hoffnung im Frost | D12: Bibliothek | E12: 1 | F12: =IFERROR(VLOOKUP(B12,Kartendaten!$A$5:$U$94,5,FALSE),"UNBEKANNT") | G12: =IFERROR(VLOOKUP(B12,Kartendaten!$A$5:$U$94,2,FALSE),"UNBEKANNT") | H12: =IFERROR(VLOOKUP(B12,Kartendaten!$A$5:$U$94,3,FALSE),"UNBEKANNT") | I12: Mana für teure Helden; verteilt beim Eintritt +1/+1-Marken | J12: Icewind Dale – Rime of the Frostmaiden · Janna | K12: Giada gibt Mana für teure Helden und verteilt beim Eintritt eine +1/+1-Marke – Cleemoes Lieder, die den Gefährten im Frost Hoffnung (und einen kleinen Schub) geben. | L12: =IFERROR(IF(AND(VLOOKUP(B12,Kartendaten!$A$5:$U$94,6,FALSE)="legal",VLOOKUP(B12,Kartendaten!$A$5:$U$94,19,FALSE)="Nein",VLOOKUP(B12,Kartendaten!$A$5:$U$94,20,FALSE)="Ja",VLOOKUP(B12,Kartendaten!$A$5:$U$94,21,FALSE)="Ja",OR(F12="Standardland",SUMIF($B$5:$B$104,B12,$E$5:$E$104)=1)),"OK","PRÜFEN"),"PRÜFEN") | M12: https://scryfall.com/card/fdn/141/giada-font-of-hope?utm_source=api | N12: https://wuerfelwaechter.de/Charakter/Details/72 | O12: =IFERROR(VLOOKUP(B12,Kartendaten!$A$5:$U$94,4,FALSE),"UNBEKANNT") | P12: =IF(ISNUMBER(SEARCH("Legendary",O12)),"Ja","Nein")
A13: 9 | B13: Linden, the Steadfast Queen | C13: Lichtträger Duvek, Lathanders Beistand | D13: Bibliothek | E13: 1 | F13: =IFERROR(VLOOKUP(B13,Kartendaten!$A$5:$U$94,5,FALSE),"UNBEKANNT") | G13: =IFERROR(VLOOKUP(B13,Kartendaten!$A$5:$U$94,2,FALSE),"UNBEKANNT") | H13: =IFERROR(VLOOKUP(B13,Kartendaten!$A$5:$U$94,3,FALSE),"UNBEKANNT") | I13: Lebenspunkte bei jedem Angriff mit einer weißen Kreatur; stabiles Fundament | J13: Icewind Dale – Rime of the Frostmaiden · Hendrik | K13: Linden schenkt Leben, sobald eine weiße Kreatur angreift – Duvek, der Priester Lathanders, der der vorrückenden Gruppe beisteht und Mut zuspricht. | L13: =IFERROR(IF(AND(VLOOKUP(B13,Kartendaten!$A$5:$U$94,6,FALSE)="legal",VLOOKUP(B13,Kartendaten!$A$5:$U$94,19,FALSE)="Nein",VLOOKUP(B13,Kartendaten!$A$5:$U$94,20,FALSE)="Ja",VLOOKUP(B13,Kartendaten!$A$5:$U$94,21,FALSE)="Ja",OR(F13="Standardland",SUMIF($B$5:$B$104,B13,$E$5:$E$104)=1)),"OK","PRÜFEN"),"PRÜFEN") | M13: https://scryfall.com/card/fdn/737/linden-the-steadfast-queen?utm_source=api | N13: https://wuerfelwaechter.de/Charakter/Details/55 | O13: =IFERROR(VLOOKUP(B13,Kartendaten!$A$5:$U$94,4,FALSE),"UNBEKANNT") | P13: =IF(ISNUMBER(SEARCH("Legendary",O13)),"Ja","Nein")
A14: 10 | B14: Svyelun of Sea and Sky | C14: Neriton, Geduld der Tiefe | D14: Bibliothek | E14: 1 | F14: =IFERROR(VLOOKUP(B14,Kartendaten!$A$5:$U$94,5,FALSE),"UNBEKANNT") | G14: =IFERROR(VLOOKUP(B14,Kartendaten!$A$5:$U$94,2,FALSE),"UNBEKANNT") | H14: =IFERROR(VLOOKUP(B14,Kartendaten!$A$5:$U$94,3,FALSE),"UNBEKANNT") | I14: Nahezu unblockbarer, unzerstörbarer Körper; Kartenzug beim Angriff | J14: Icewind Dale – Rime of the Frostmaiden · Sebastian | K14: Svyelun ist eine merfolkhafte Meeresgottheit: unzerstörbar und kaum blockbar, solange Verbündete da sind, mit Kartenzug beim Angriff – Neritons ‚Geduld, dann Kraft‘. | L14: =IFERROR(IF(AND(VLOOKUP(B14,Kartendaten!$A$5:$U$94,6,FALSE)="legal",VLOOKUP(B14,Kartendaten!$A$5:$U$94,19,FALSE)="Nein",VLOOKUP(B14,Kartendaten!$A$5:$U$94,20,FALSE)="Ja",VLOOKUP(B14,Kartendaten!$A$5:$U$94,21,FALSE)="Ja",OR(F14="Standardland",SUMIF($B$5:$B$104,B14,$E$5:$E$104)=1)),"OK","PRÜFEN"),"PRÜFEN") | M14: https://scryfall.com/card/lcc/175/svyelun-of-sea-and-sky?utm_source=api | N14: https://wuerfelwaechter.de/Charakter/Details/33 | O14: =IFERROR(VLOOKUP(B14,Kartendaten!$A$5:$U$94,4,FALSE),"UNBEKANNT") | P14: =IF(ISNUMBER(SEARCH("Legendary",O14)),"Ja","Nein")
A15: 11 | B15: Elenda, the Dusk Rose | C15: Sharalaq – „Ich bin euer Schild!“ | D15: Bibliothek | E15: 1 | F15: =IFERROR(VLOOKUP(B15,Kartendaten!$A$5:$U$94,5,FALSE),"UNBEKANNT") | G15: =IFERROR(VLOOKUP(B15,Kartendaten!$A$5:$U$94,2,FALSE),"UNBEKANNT") | H15: =IFERROR(VLOOKUP(B15,Kartendaten!$A$5:$U$94,3,FALSE),"UNBEKANNT") | I15: Wächst mit jedem Kreaturentod; fällt sie, steht eine ganze Schatten-Armee auf | J15: Sturm, Staub und Schatten · Dani | K15: Sharas ganze Rolle ist der Schild, der sich opfert – und der Schatten als treuer Begleiter. Elenda wächst über das Spiel, hält als Blocker stand und hinterlässt beim Sterben eine Armee: stärker und dramatischer als ein 2/1-Opferzauber. | L15: =IFERROR(IF(AND(VLOOKUP(B15,Kartendaten!$A$5:$U$94,6,FALSE)="legal",VLOOKUP(B15,Kartendaten!$A$5:$U$94,19,FALSE)="Nein",VLOOKUP(B15,Kartendaten!$A$5:$U$94,20,FALSE)="Ja",VLOOKUP(B15,Kartendaten!$A$5:$U$94,21,FALSE)="Ja",OR(F15="Standardland",SUMIF($B$5:$B$104,B15,$E$5:$E$104)=1)),"OK","PRÜFEN"),"PRÜFEN") | M15: https://scryfall.com/card/lcc/268/elenda-the-dusk-rose?utm_source=api | N15: https://wuerfelwaechter.de/Charakter/Details/24 | O15: =IFERROR(VLOOKUP(B15,Kartendaten!$A$5:$U$94,4,FALSE),"UNBEKANNT") | P15: =IF(ISNUMBER(SEARCH("Legendary",O15)),"Ja","Nein")
A16: 12 | B16: Talrand, Sky Summoner | C16: Quill, Hüter der verlorenen Seelen | D16: Bibliothek | E16: 1 | F16: =IFERROR(VLOOKUP(B16,Kartendaten!$A$5:$U$94,5,FALSE),"UNBEKANNT") | G16: =IFERROR(VLOOKUP(B16,Kartendaten!$A$5:$U$94,2,FALSE),"UNBEKANNT") | H16: =IFERROR(VLOOKUP(B16,Kartendaten!$A$5:$U$94,3,FALSE),"UNBEKANNT") | I16: Baut aus jedem Spontanzauber/jeder Hexerei einen 2/2-Drachen; fliegende Armee | J16: Sturm, Staub und Schatten · Jonas | K16: Quill ist der neugierige Magier, der aus jeder aufgedeckten Geschichte etwas Neues zieht. Talrand verwandelt das Zauberbuch in eine fliegende Armee – Board-Präsenz und Kartenwert statt eines 1/3 ohne Angriffsdruck. | L16: =IFERROR(IF(AND(VLOOKUP(B16,Kartendaten!$A$5:$U$94,6,FALSE)="legal",VLOOKUP(B16,Kartendaten!$A$5:$U$94,19,FALSE)="Nein",VLOOKUP(B16,Kartendaten!$A$5:$U$94,20,FALSE)="Ja",VLOOKUP(B16,Kartendaten!$A$5:$U$94,21,FALSE)="Ja",OR(F16="Standardland",SUMIF($B$5:$B$104,B16,$E$5:$E$104)=1)),"OK","PRÜFEN"),"PRÜFEN") | M16: https://scryfall.com/card/otc/116/talrand-sky-summoner?utm_source=api | N16: https://wuerfelwaechter.de/Charakter/Details/26 | O16: =IFERROR(VLOOKUP(B16,Kartendaten!$A$5:$U$94,4,FALSE),"UNBEKANNT") | P16: =IF(ISNUMBER(SEARCH("Legendary",O16)),"Ja","Nein")
... A104: 100 | B104: The World Tree | C104: Abenteuer im Multiversum – Reise durchs All | D104: Bibliothek | E104: 1 | F104: =IFERROR(VLOOKUP(B104,Kartendaten!$A$5:$U$94,5,FALSE),"UNBEKANNT") | G104: =IFERROR(VLOOKUP(B104,Kartendaten!$A$5:$U$94,2,FALSE),"UNBEKANNT") | H104: =IFERROR(VLOOKUP(B104,Kartendaten!$A$5:$U$94,3,FALSE),"UNBEKANNT") | I104: Fünffarbige Manaquelle; großer Legenden-/Götter-Finisher aus der Bibliothek | J104: Abenteuer im Multiversum · Insider „Abenteuer im Multiversum“ (Zeile 17, Kampagnen-Format) | K104: ‚Abenteuer im Multiversum‘ (SL: Dani) – die Science-Fiction-/Space-One-Shots mit KORG, Dr. Boom, G.I.E.G., Jack, Claptron. The World Tree ist das Portal zwischen den Welten. | L104: =IFERROR(IF(AND(VLOOKUP(B104,Kartendaten!$A$5:$U$94,6,FALSE)="legal",VLOOKUP(B104,Kartendaten!$A$5:$U$94,19,FALSE)="Nein",VLOOKUP(B104,Kartendaten!$A$5:$U$94,20,FALSE)="Ja",VLOOKUP(B104,Kartendaten!$A$5:$U$94,21,FALSE)="Ja",OR(F104="Standardland",SUMIF($B$5:$B$104,B104,$E$5:$E$104)=1)),"OK","PRÜFEN"),"PRÜFEN") | M104: https://scryfall.com/card/khm/275/the-world-tree?utm_source=api | N104: https://wuerfelwaechter.de/Kampagne/Details/7 | O104: =IFERROR(VLOOKUP(B104,Kartendaten!$A$5:$U$94,4,FALSE),"UNBEKANNT") | P104: =IF(ISNUMBER(SEARCH("Legendary",O104)),"Ja","Nein")

Sheet Designs
A1: 100 Designs · Figuren, Insider und Landschaften
A2: Bildbriefings für die neue Gestaltung. Flavor ist kein Regeltext; die echte Karte bleibt maßgeblich.
A4: Nr. | B4: Echte MTG-Karte | C4: Neuer Designname | D4: Konkretes Bildbriefing | E4: Flavor-Vorschlag | F4: Bewusste Adaption / Regelgrenze | G4: Bezug / Beleg | H4: Bildreferenz / URL
A5: 1 | B5: Esika, God of the Tree | C5: WürfelWächter · Wächter am Portal aller Geschichten | D5: Vorderseite: das Maskottchen exakt nach Logo – geschlossener blau-silberner Helm, WW-Emblem, wachsam vor einem leuchtenden fünffarbigen Torbogen; die Silhouetten der Kampagnen-Helden stehen ruhig neben ihm, alle in Bereitschaft. Rückseite (The Prismatic Bridge): nur der Torbogen als Regenbogen-Portal über einem aufgeschlagenen Logbuch, aus dem gerade eine Heldengestalt tritt. | E5: Der Wächter senkt die Wache nie – und hinter ihm öffnet sich das Portal. | F5: Modale Doppelkarte, unverändert (God // Legendary Enchantment). Vorderseite: Wachsamkeit und '{T}: ein Mana beliebiger Farbe' für andere legendäre Kreaturen – gedruckter Text, keine Würfelregel. Rückseite: pro Aufwertung eine Kreatur/Planeswalker aus der Bibliothek ins Spiel, Rest nach unten – gedruckter Text. Aus der Kommandozone ist immer nur eine Seite gleichzeitig im Spiel. | G5: WürfelWächter · Maskottchen / Commander | H5: https://wuerfelwaechter.de/images/WuerfelWaechter_bearbeitet.webp
A6: 2 | B6: Aurelia, the Warleader | C6: Jonvus Sonnenzorn-ChewChew, führt den Bund | D6: Jonvus in grün-silberner Rüstung mit der Drachenlanze, im Sturzflug an der Spitze der Octo’Talis-Formation; hinter ihm richtet sich die Gruppe zum zweiten Angriff auf. Die Ascheschrift seines verbrannten Pakts weht als Schweif hinter ihm. | E6: Hingabe ist kein Rückzug. Wir gehen voran. | F6: Legendary Creature — Angel Warrior bleibt unverändert. Beim ersten Angriff jede Runde: enttappe die angreifenden Kreaturen und es folgt eine zusätzliche Kampfphase – gedruckter Text, kein Schwur-Zusatz, keine Aura. | G6: Die Legende des Rubindrachen · Jonas | H6: https://wuerfelwaechter.de/images/Charakter/21_Jonvus.webp
A7: 3 | B7: Selvala, Explorer Returned | C7: Vorian Flammenzorn, zurück unter Sternen | D7: Vorian als Eladrin mit rotem Haar und Blattgewand, die Ilithkar-Schädelmaske am Gürtel; über ihm ein Sternbild-Zirkel, dessen Linien in Manafunken zerfallen, die an alle vier Himmelsrichtungen gehen. | E7: Wer aus dem Dienst Asmodeus’ zurückkehrt, teilt das Licht. | F7: Elf Scout bleibt. Parley wird von JEDEM Spieler mitentschieden; die zwei Lebenspunkte und die Karte für die Gegner sind Teil des echten Textes und werden nicht weggelassen. | G7: Die Legende des Rubindrachen · Kevin | H7: https://wuerfelwaechter.de/images/Charakter/58_Vorian.webp
A8: 4 | B8: Myrel, Shield of Argive | C8: Hemish, Bannerträger Octo’Talis’ | D8: Hemish als Ork nach Porträt, das Octo’Talis-Banner im Sturm; aus dem Bannerschatten treten schemenhafte Soldaten-Spielsteine. Schützender Lichtwall vor der Gruppe. | E8: Wir schaffen das, immerhin sind wir Octotalis. | F8: Human Soldier statt Ork-Bannerträger. Die Sperre gilt erst ab deinem zweiten Zug und nur während deines Kampfes; keine dauerhafte Stax-Regel. | G8: Die Legende des Rubindrachen · Jan | H8: https://wuerfelwaechter.de/images/Charakter/36_Hemish.webp
A9: 5 | B9: Ranar the Ever-Watchful | C9: Susi Lichtschwur, mit leichtem Schritt | D9: Susi nach dunklem Porträt, mit leichtem Schritt an einem fremden Zauberbuch vorbei; ein zweites, halb durchscheinendes Abbild von ihr tritt gerade aus dem Nichts zurück ins Bild. | E9: Hey du da! Ich bin Susi und wir sind Octo Talis. | F9: Spirit Warrior bleibt. 'Foretell / Ausblenden' und die Geist-Spielsteine sind der echte Kartentext; kein Diebstahl fremder Karten, keine Vampir-Regeln. | G9: Die Legende des Rubindrachen · Janna | H9: https://wuerfelwaechter.de/images/Charakter/70_Susi.webp
A10: 6 | B10: Arahbo, Roar of the World | C10: Damon Driftwood, Stärke schützt | D10: Weißmähniger Leonin nach Porträt im Schneesturm, schützend über der kleinen Cleemoe; ein löwenförmiger Lichtumriss legt sich wie ein Schild um beide. | E10: Werde stärker. Nicht härter. Stärke schützt. Härte bricht. | F10: Cat Avatar bleibt. Der 'Eminence'-Bonus wirkt schon aus der Kommandozone – das ist der gedruckte Text, keine neue Fähigkeit. Nur eine Katze pro Kampf. | G10: Icewind Dale – Rime of the Frostmaiden · Jonas | H10: https://wuerfelwaechter.de/images/Charakter/28_Damon_639202705446649369.webp
A11: 7 | B11: Kardur, Doomscourge | C11: Mumpfi Nebelhauer, Schuldner der Phaerimm | D11: Nilpferd-Offizier mit zwei Pistolen auf einer treibenden Eisscholle; das verbotene Phaerimm-Buch schwebt offen neben ihm und schickt dünne Fäden zu den Silhouetten seiner alten Gefährten, die sich bereits gegeneinander wenden. | E11: Jeden Kupfer zurückgezahlt. Und trotzdem alle gegen mich aufgebracht. | F11: Legendary Creature — Demon Berserker bleibt der Regeltyp. ETB: jeder Gegner opfert eine Kreatur. Danach: greift eine Kreatur an, die ein Gegner kontrolliert, verliert dieser Spieler 1 Leben – gedruckter Text, kein wählbarer Sabotage-Effekt. | G11: Icewind Dale – Rime of the Frostmaiden · Jonas | H11: https://wuerfelwaechter.de/images/Charakter/29_Nebelhauer_639241235686099760.webp
A12: 8 | B12: Giada, Font of Hope | C12: Cleemoe Driftwood, Hoffnung im Frost | D12: Cleemoe mit dunklen Hörnern und goldener Rüstung nach Porträt; sie singt, und aus dem Atem werden warme Lichtpartikel, die sich als Marken auf die Gefährten legen. | E12: Jedes Wesen hat Hoffnung verdient. | F12: Angel statt Tiefling-Paladin. 'Engel'-Bezüge im Text bleiben – die Marke geht beim Eintritt an eine andere legendäre oder eine Engelskreatur, wie gedruckt. Keine Paladin-Aura. | G12: Icewind Dale – Rime of the Frostmaiden · Janna | H12: https://wuerfelwaechter.de/images/Charakter/72_Klee.webp
A13: 9 | B13: Linden, the Steadfast Queen | C13: Lichtträger Duvek, Lathanders Beistand | D13: Duvek nach Porträt, kahlköpfig, in schlichtem Gewand mit Sonnensymbol; er hebt die Hand und ein sanftes Morgenlicht (Lathander) fällt auf die vorrückende Gruppe. | E13: Icewind Dale braucht Hilfe – also bin ich hier. | F13: Human Noble bleibt. Lebensgewinn nur, wenn eine weiße Kreatur angreift – gedruckter Text, keine Kleriker-Domäne, kein Massenheilen. | G13: Icewind Dale – Rime of the Frostmaiden · Hendrik | H13: https://wuerfelwaechter.de/images/Charakter/55_Duvek.webp
A14: 10 | B14: Svyelun of Sea and Sky | C14: Neriton, Geduld der Tiefe | D14: Neriton nach blauhäutigem Porträt auf schwarzem Eis; um ihn eine ruhige, kreisende Wasserwand, die erst beim Ausfall zur Strömung wird. Gischt und Ruhe zugleich. | E14: Tiefe ist Geduld. Strömung ist Kraft. | F14: Merfolk God bleibt. Unzerstörbarkeit und Unblockbarkeit gelten NUR, solange du einen weiteren Merfolk kontrollierst – gedruckte Bedingung, keine Mönchs-Sonderregeln. | G14: Icewind Dale – Rime of the Frostmaiden · Sebastian | H14: https://wuerfelwaechter.de/images/Charakter/33_Neriton.webp
A15: 11 | B15: Elenda, the Dusk Rose | C15: Sharalaq – „Ich bin euer Schild!“ | D15: Shara vor der Gruppe, der eigene Schatten zu einem großen Schild geformt; um ihn her lösen sich bereits einzelne Schattenfetzen, die die Umrisse künftiger Verbündeter andeuten. | E15: Ich bin euer Schild! … und wenn ich falle, bin ich viele. | F15: Legendary Creature — Vampire Cleric bleibt unverändert. Jeder Kreaturentod (auch gegnerisch) legt eine +1/+1-Marke auf Elenda; stirbt sie, erzeugst du X 1/1-Vampire mit Lebensverknüpfung (X = ihre Stärke) – gedruckter Text. Kein Echo-Knight-, kein Erzfee-Text. | G15: Sturm, Staub und Schatten · Dani | H15: https://wuerfelwaechter.de/images/Charakter/24_Shara_639243807374018146.webp
A16: 12 | B16: Talrand, Sky Summoner | C16: Quill, Hüter der verlorenen Seelen | D16: Quill als kleiner Gnom über einem aufgeschlagenen Foliant; aus den Seiten steigen blasse, drachenförmige Seelenlichter auf und kreisen schützend um die Gruppe. | E16: Die Welt bietet Geheimnisse – und jedes ruft etwas herbei. | F16: Legendary Creature — Merfolk Wizard bleibt der Regeltyp. Wann immer du einen Spontanzauber oder eine Hexerei wirkst, erzeuge einen 2/2 blauen Drake-Spielstein mit Flug – gedruckter Text. Keine Seelen-Sammel-Mechanik als Regel. | G16: Sturm, Staub und Schatten · Jonas | H16: https://wuerfelwaechter.de/images/Charakter/26_Quill_639241218056167554.webp
... A104: 100 | B104: The World Tree | C104: Abenteuer im Multiversum – Reise durchs All | D104: Ein gewaltiger Weltenbaum, dessen Äste verschiedene Planeten und Raumstationen tragen; kleine Sci-Fi-Silhouetten (KORG, Dr. Boom, Jack) reisen zwischen den Ästen. | E104: Eine Truppe aus Raumfahrern, Technikern und Zeitreisenden – und ein Baum, der jede Welt trägt. | F104: Land bleibt. '{T}: ein Mana beliebiger Farbe' erst ab 5+ Ländern; die {5}{G}{W}{U}{B}{R}-Fähigkeit holt Götter/Legenden aufs Feld – gedruckter Text. | G104: Abenteuer im Multiversum · Insider „Abenteuer im Multiversum“ (Zeile 17, Kampagnen-Format) | H104: https://wuerfelwaechter.de/images/Kampagne/7_Abenteuer_im_Multiversum.webp

Sheet Bildpaare
A1: Bildpaare · echte Originalkarte und WürfelWächter-Referenz
A2: Automatisch heruntergeladene Kartenbilder (Scryfall) und Webreferenzen (wuerfelwaechter.de). Die neuen Illustrationen entstehen daraus.
A4: Nr. | B4: Echte Originalkarte | C4: Vorhandene Webreferenz | D4: Original → WürfelWächter | E4: Motiv für die neue Illustration | F4: Regelgrenze der Gestaltung
A5: 1 | D5: Esika, God of the Tree WürfelWächter · Wächter am Portal aller Geschichten | E5: Vorderseite: das Maskottchen exakt nach Logo – geschlossener blau-silberner Helm, WW-Emblem, wachsam vor einem leuchtenden fünffarbigen Torbogen; die Silhouetten der Kampagnen-Helden stehen ruhig neben ihm, alle in Bereitschaft. Rückseite (The Prismatic Bridge): nur der Torbogen als Regenbogen-Portal über einem aufgeschlagenen Logbuch, aus dem gerade eine Heldengestalt tritt. | F5: Modale Doppelkarte, unverändert (God // Legendary Enchantment). Vorderseite: Wachsamkeit und '{T}: ein Mana beliebiger Farbe' für andere legendäre Kreaturen – gedruckter Text, keine Würfelregel. Rückseite: pro Aufwertung eine Kreatur/Planeswalker aus der Bibliothek ins Spiel, Rest nach unten – gedruckter Text. Aus der Kommandozone ist immer nur eine Seite gleichzeitig im Spiel.
A6: 2 | D6: Aurelia, the Warleader Jonvus Sonnenzorn-ChewChew, führt den Bund | E6: Jonvus in grün-silberner Rüstung mit der Drachenlanze, im Sturzflug an der Spitze der Octo’Talis-Formation; hinter ihm richtet sich die Gruppe zum zweiten Angriff auf. Die Ascheschrift seines verbrannten Pakts weht als Schweif hinter ihm. | F6: Legendary Creature — Angel Warrior bleibt unverändert. Beim ersten Angriff jede Runde: enttappe die angreifenden Kreaturen und es folgt eine zusätzliche Kampfphase – gedruckter Text, kein Schwur-Zusatz, keine Aura.
A7: 3 | D7: Selvala, Explorer Returned Vorian Flammenzorn, zurück unter Sternen | E7: Vorian als Eladrin mit rotem Haar und Blattgewand, die Ilithkar-Schädelmaske am Gürtel; über ihm ein Sternbild-Zirkel, dessen Linien in Manafunken zerfallen, die an alle vier Himmelsrichtungen gehen. | F7: Elf Scout bleibt. Parley wird von JEDEM Spieler mitentschieden; die zwei Lebenspunkte und die Karte für die Gegner sind Teil des echten Textes und werden nicht weggelassen.
A8: 4 | D8: Myrel, Shield of Argive Hemish, Bannerträger Octo’Talis’ | E8: Hemish als Ork nach Porträt, das Octo’Talis-Banner im Sturm; aus dem Bannerschatten treten schemenhafte Soldaten-Spielsteine. Schützender Lichtwall vor der Gruppe. | F8: Human Soldier statt Ork-Bannerträger. Die Sperre gilt erst ab deinem zweiten Zug und nur während deines Kampfes; keine dauerhafte Stax-Regel.
A9: 5 | D9: Ranar the Ever-Watchful Susi Lichtschwur, mit leichtem Schritt | E9: Susi nach dunklem Porträt, mit leichtem Schritt an einem fremden Zauberbuch vorbei; ein zweites, halb durchscheinendes Abbild von ihr tritt gerade aus dem Nichts zurück ins Bild. | F9: Spirit Warrior bleibt. 'Foretell / Ausblenden' und die Geist-Spielsteine sind der echte Kartentext; kein Diebstahl fremder Karten, keine Vampir-Regeln.
A10: 6 | D10: Arahbo, Roar of the World Damon Driftwood, Stärke schützt | E10: Weißmähniger Leonin nach Porträt im Schneesturm, schützend über der kleinen Cleemoe; ein löwenförmiger Lichtumriss legt sich wie ein Schild um beide. | F10: Cat Avatar bleibt. Der 'Eminence'-Bonus wirkt schon aus der Kommandozone – das ist der gedruckte Text, keine neue Fähigkeit. Nur eine Katze pro Kampf.
A11: 7 | D11: Kardur, Doomscourge Mumpfi Nebelhauer, Schuldner der Phaerimm | E11: Nilpferd-Offizier mit zwei Pistolen auf einer treibenden Eisscholle; das verbotene Phaerimm-Buch schwebt offen neben ihm und schickt dünne Fäden zu den Silhouetten seiner alten Gefährten, die sich bereits gegeneinander wenden. | F11: Legendary Creature — Demon Berserker bleibt der Regeltyp. ETB: jeder Gegner opfert eine Kreatur. Danach: greift eine Kreatur an, die ein Gegner kontrolliert, verliert dieser Spieler 1 Leben – gedruckter Text, kein wählbarer Sabotage-Effekt.
A12: 8 | D12: Giada, Font of Hope Cleemoe Driftwood, Hoffnung im Frost | E12: Cleemoe mit dunklen Hörnern und goldener Rüstung nach Porträt; sie singt, und aus dem Atem werden warme Lichtpartikel, die sich als Marken auf die Gefährten legen. | F12: Angel statt Tiefling-Paladin. 'Engel'-Bezüge im Text bleiben – die Marke geht beim Eintritt an eine andere legendäre oder eine Engelskreatur, wie gedruckt. Keine Paladin-Aura.
A13: 9 | D13: Linden, the Steadfast Queen Lichtträger Duvek, Lathanders Beistand | E13: Duvek nach Porträt, kahlköpfig, in schlichtem Gewand mit Sonnensymbol; er hebt die Hand und ein sanftes Morgenlicht (Lathander) fällt auf die vorrückende Gruppe. | F13: Human Noble bleibt. Lebensgewinn nur, wenn eine weiße Kreatur angreift – gedruckter Text, keine Kleriker-Domäne, kein Massenheilen.
A14: 10 | D14: Svyelun of Sea and Sky Neriton, Geduld der Tiefe | E14: Neriton nach blauhäutigem Porträt auf schwarzem Eis; um ihn eine ruhige, kreisende Wasserwand, die erst beim Ausfall zur Strömung wird. Gischt und Ruhe zugleich. | F14: Merfolk God bleibt. Unzerstörbarkeit und Unblockbarkeit gelten NUR, solange du einen weiteren Merfolk kontrollierst – gedruckte Bedingung, keine Mönchs-Sonderregeln.
A15: 11 | D15: Elenda, the Dusk Rose Sharalaq – „Ich bin euer Schild!“ | E15: Shara vor der Gruppe, der eigene Schatten zu einem großen Schild geformt; um ihn her lösen sich bereits einzelne Schattenfetzen, die die Umrisse künftiger Verbündeter andeuten. | F15: Legendary Creature — Vampire Cleric bleibt unverändert. Jeder Kreaturentod (auch gegnerisch) legt eine +1/+1-Marke auf Elenda; stirbt sie, erzeugst du X 1/1-Vampire mit Lebensverknüpfung (X = ihre Stärke) – gedruckter Text. Kein Echo-Knight-, kein Erzfee-Text.
A16: 12 | D16: Talrand, Sky Summoner Quill, Hüter der verlorenen Seelen | E16: Quill als kleiner Gnom über einem aufgeschlagenen Foliant; aus den Seiten steigen blasse, drachenförmige Seelenlichter auf und kreisen schützend um die Gruppe. | F16: Legendary Creature — Merfolk Wizard bleibt der Regeltyp. Wann immer du einen Spontanzauber oder eine Hexerei wirkst, erzeuge einen 2/2 blauen Drake-Spielstein mit Flug – gedruckter Text. Keine Seelen-Sammel-Mechanik als Regel.
... A104: 100 | D104: The World Tree Abenteuer im Multiversum – Reise durchs All | E104: Ein gewaltiger Weltenbaum, dessen Äste verschiedene Planeten und Raumstationen tragen; kleine Sci-Fi-Silhouetten (KORG, Dr. Boom, Jack) reisen zwischen den Ästen. | F104: Land bleibt. '{T}: ein Mana beliebiger Farbe' erst ab 5+ Ländern; die {5}{G}{W}{U}{B}{R}-Fähigkeit holt Götter/Legenden aufs Feld – gedruckter Text.

Sheet Kartendaten
A1: Die echten Karten · verifizierte Daten
A2: Einzigartige Originale · englischer Oracle-Text · Scryfall API · Papierdrucke bis 07.09.2026 · Commander-Status.
A4: Originalkarte | B4: Manakosten | C4: Manawert | D4: Original-Typzeile | E4: Haupttyp | F4: Commander-Status | G4: Farbidentität | H4: Stärke | I4: Widerstandskraft | J4: Loyalität | K4: Oracle-Regeltext (EN, unverändert) | L4: Set | M4: Sammlernummer | N4: Druckdatum | O4: Oracle-ID | P4: Original / Regeln | Q4: Bild-URL | R4: Original-Illustration | S4: Nur digital? | T4: Papierausgabe? | U4: Bis Stichtag?
A5: Esika, God of the Tree | B5: {1}{G}{G} // {W}{U}{B}{R}{G} | C5: 3 | D5: Legendary Creature — God // Legendary Enchantment | E5: Kreatur | F5: legal | G5: BGRUW | H5: 1 | I5: 4 | K5: Vigilance {T}: Add one mana of any color. Other legendary creatures you control have vigilance and "{T}: Add one mana of any color." // At the beginning of your upkeep, reveal cards from the top of your library until you reveal a creature or planeswalker card. Put that card onto the battlefield and the rest on the bottom of your library in a random order. | L5: KHM | M5: 168 | N5: 2021-02-05 | P5: https://scryfall.com/card/khm/168/esika-god-of-the-tree-the-prismatic-bridge?utm_source=api | Q5: https://cards.scryfall.io/normal/front/f/6/f6cd7465-9dd0-473c-ac5e-dd9e2f22f5f6.jpg?1783928221 | R5: Johannes Voss | S5: Nein | T5: Ja | U5: Ja
A6: Aurelia, the Warleader | B6: {2}{R}{R}{W}{W} | C6: 6 | D6: Legendary Creature — Angel | E6: Kreatur | F6: legal | G6: RW | H6: 3 | I6: 4 | K6: Flying, vigilance, haste Whenever Aurelia attacks for the first time each turn, untap all creatures you control. After this phase, there is an additional combat phase. | L6: FDN | M6: 651 | N6: 2024-11-15 | P6: https://scryfall.com/card/fdn/651/aurelia-the-warleader?utm_source=api | Q6: https://cards.scryfall.io/normal/front/b/c/bc6ffc1c-575b-4116-83c9-d13b29886c35.jpg?1783908915 | R6: Slawomir Maniak | S6: Nein | T6: Ja | U6: Ja
A7: Selvala, Explorer Returned | B7: {1}{G}{W} | C7: 3 | D7: Legendary Creature — Elf Scout | E7: Kreatur | F7: legal | G7: GW | H7: 2 | I7: 4 | K7: Parley — {T}: Each player reveals the top card of their library. For each nonland card revealed this way, add {G} and you gain 1 life. Then each player draws a card. (Activate only as an instant.) | L7: MKC | M7: 218 | N7: 2024-02-09 | P7: https://scryfall.com/card/mkc/218/selvala-explorer-returned?utm_source=api | Q7: https://cards.scryfall.io/normal/front/2/8/28c1b84a-a21b-4df1-9fc9-5b387fb56810.jpg?1786381273 | R7: Tyler Jacobson | S7: Nein | T7: Ja | U7: Ja
A8: Myrel, Shield of Argive | B8: {3}{W} | C8: 4 | D8: Legendary Creature — Human Soldier | E8: Kreatur | F8: legal | G8: W | H8: 3 | I8: 4 | K8: During your turn, your opponents can't cast spells or activate abilities of artifacts, creatures, or enchantments. Whenever Myrel attacks, create X 1/1 colorless Soldier artifact creature tokens, where X is the number of Soldiers you control. | L8: BRO | M8: 18 | N8: 2022-11-18 | P8: https://scryfall.com/card/bro/18/myrel-shield-of-argive?utm_source=api | Q8: https://cards.scryfall.io/normal/front/e/6/e632ed57-bb00-4493-adef-7b4805edd7ea.jpg?1783920129 | R8: Ryan Pancoast | S8: Nein | T8: Ja | U8: Ja
A9: Ranar the Ever-Watchful | B9: {2}{W}{U} | C9: 4 | D9: Legendary Creature — Spirit Warrior | E9: Kreatur | F9: legal | G9: UW | H9: 2 | I9: 3 | K9: Flying, vigilance The first card you foretell each turn costs {0} to foretell. Whenever one or more cards are put into exile from your hand or a spell or ability you control exiles one or more permanents from the battlefield, create a 1/1 white Spirit creature token with flying. | L9: KHC | M9: 2 | N9: 2021-02-05 | P9: https://scryfall.com/card/khc/2/ranar-the-ever-watchful?utm_source=api | Q9: https://cards.scryfall.io/normal/front/1/c/1c8c41dd-8551-4ce8-a9be-9b9f65718852.jpg?1783928341 | R9: Kieran Yanner | S9: Nein | T9: Ja | U9: Ja
A10: Arahbo, Roar of the World | B10: {3}{G}{W} | C10: 5 | D10: Legendary Creature — Cat Avatar | E10: Kreatur | F10: legal | G10: GW | H10: 5 | I10: 5 | K10: Eminence — At the beginning of combat on your turn, if Arahbo is in the command zone or on the battlefield, another target Cat you control gets +3/+3 until end of turn. Whenever another Cat you control attacks, you may pay {1}{G}{W}. If you do, it gains trample and gets +X/+X until end of turn, where X is its power. | L10: C17 | M10: 35 | N10: 2017-08-25 | P10: https://scryfall.com/card/c17/35/arahbo-roar-of-the-world?utm_source=api | Q10: https://cards.scryfall.io/normal/front/8/1/81dc3d00-97cd-4549-b5a4-15a1e08767f5.jpg?1783935939 | R10: Jesper Ejsing | S10: Nein | T10: Ja | U10: Ja
A11: Kardur, Doomscourge | B11: {2}{B}{R} | C11: 4 | D11: Legendary Creature — Demon Berserker | E11: Kreatur | F11: legal | G11: BR | H11: 4 | I11: 3 | K11: When Kardur enters, until your next turn, creatures your opponents control attack each combat if able and attack a player other than you if able. Whenever an attacking creature dies, each opponent loses 1 life and you gain 1 life. | L11: DSC | M11: 223 | N11: 2024-09-27 | P11: https://scryfall.com/card/dsc/223/kardur-doomscourge?utm_source=api | Q11: https://cards.scryfall.io/normal/front/7/c/7c0f7712-7bbf-471b-8107-3a49cf922ad9.jpg?1783909592 | R11: Chris Rahn | S11: Nein | T11: Ja | U11: Ja
A12: Giada, Font of Hope | B12: {1}{W} | C12: 2 | D12: Legendary Creature — Angel | E12: Kreatur | F12: legal | G12: W | H12: 2 | I12: 2 | K12: Flying, vigilance Each other Angel you control enters with an additional +1/+1 counter on it for each Angel you already control. {T}: Add {W}. Spend this mana only to cast an Angel spell. | L12: FDN | M12: 141 | N12: 2024-11-15 | P12: https://scryfall.com/card/fdn/141/giada-font-of-hope?utm_source=api | Q12: https://cards.scryfall.io/normal/front/8/a/8ae6fc26-cfad-4da8-98d9-49c27c24d293.jpg?1783909085 | R12: Kai Carpenter | S12: Nein | T12: Ja | U12: Ja
A13: Linden, the Steadfast Queen | B13: {W}{W}{W} | C13: 3 | D13: Legendary Creature — Human Noble | E13: Kreatur | F13: legal | G13: W | H13: 3 | I13: 3 | K13: Vigilance (Attacking doesn't cause this creature to tap.) Whenever a white creature you control attacks, you gain 1 life. | L13: FDN | M13: 737 | N13: 2026-04-24 | P13: https://scryfall.com/card/fdn/737/linden-the-steadfast-queen?utm_source=api | Q13: https://cards.scryfall.io/normal/front/e/0/e0bb07cd-9b74-4ba7-8089-27a565d74197.jpg?1787563118 | R13: Ryan Pancoast | S13: Nein | T13: Ja | U13: Ja
A14: Svyelun of Sea and Sky | B14: {1}{U}{U} | C14: 3 | D14: Legendary Creature — Merfolk God | E14: Kreatur | F14: legal | G14: U | H14: 3 | I14: 4 | K14: Svyelun has indestructible as long as you control at least two other Merfolk. Whenever Svyelun attacks, draw a card. Other Merfolk you control have ward {1}. (Whenever another Merfolk you control becomes the target of a spell or ability an opponent controls, counter it unless that player pays {1}.) | L14: LCC | M14: 175 | N14: 2023-11-17 | P14: https://scryfall.com/card/lcc/175/svyelun-of-sea-and-sky?utm_source=api | Q14: https://cards.scryfall.io/normal/front/0/1/01f5ab00-5305-4ac4-915d-feeb591f9389.jpg?1783913880 | R14: Seb McKinnon | S14: Nein | T14: Ja | U14: Ja
A15: Elenda, the Dusk Rose | B15: {2}{W}{B} | C15: 4 | D15: Legendary Creature — Vampire Knight | E15: Kreatur | F15: legal | G15: BW | H15: 1 | I15: 1 | K15: Lifelink Whenever another creature dies, put a +1/+1 counter on Elenda. When Elenda dies, create X 1/1 white Vampire creature tokens with lifelink, where X is Elenda's power. | L15: LCC | M15: 268 | N15: 2023-11-17 | P15: https://scryfall.com/card/lcc/268/elenda-the-dusk-rose?utm_source=api | Q15: https://cards.scryfall.io/normal/front/e/1/e18feca3-1b1b-4456-8873-25a24849a917.jpg?1783913851 | R15: Chris Rahn | S15: Nein | T15: Ja | U15: Ja
A16: Talrand, Sky Summoner | B16: {2}{U}{U} | C16: 4 | D16: Legendary Creature — Merfolk Wizard | E16: Kreatur | F16: legal | G16: U | H16: 2 | I16: 2 | K16: Whenever you cast an instant or sorcery spell, create a 2/2 blue Drake creature token with flying. | L16: OTC | M16: 116 | N16: 2024-04-19 | P16: https://scryfall.com/card/otc/116/talrand-sky-summoner?utm_source=api | Q16: https://cards.scryfall.io/normal/front/1/b/1be3ed47-072e-481a-b3d9-dc232ac4b24f.jpg?1783911937 | R16: Svetlin Velinov | S16: Nein | T16: Ja | U16: Ja
... A19: Halvar, God of Battle | B19: {2}{W}{W} // {1}{W} | C19: 4 | D19: Legendary Creature — God // Legendary Artifact — Equipment | E19: Kreatur | F19: legal | G19: W | H19: 4 | I19: 4 | K19: Creatures you control that are enchanted or equipped have double strike. At the beginning of each combat, you may attach target Aura or Equipment attached to a creature you control to target creature you control. // Equipped creature gets +2/+0 and has vigilance. Whenever equipped creature dies, return it to its owner's hand. Equip {1}{W} | L19: KHM | M19: 15 | N19: 2021-02-05 | P19: https://scryfall.com/card/khm/15/halvar-god-of-battle-sword-of-the-realms?utm_source=api | Q19: https://cards.scryfall.io/normal/front/9/7/97502411-5c93-434c-b77b-ceb2c32feae7.jpg?1783928291 | R19: Lie Setiawan | S19: Nein | T19: Ja | U19: Ja
A20: Wrenn and Seven | B20: {3}{G}{G} | C20: 5 | D20: Legendary Planeswalker — Wrenn | E20: Planeswalker | F20: legal | G20: G | J20: 5 | K20: +1: Reveal the top four cards of your library. Put all land cards revealed this way into your hand and the rest into your graveyard. 0: Put any number of land cards from your hand onto the battlefield tapped. −3: Create a green Treefolk creature token with reach and "This token's power and toughness are each equal to the number of lands you control." −8: Return all permanent cards from your graveyard to your hand. You get an emblem with "You have no maximum hand size." | L20: INR | M20: 226 | N20: 2025-01-24 | P20: https://scryfall.com/card/inr/226/wrenn-and-seven?utm_source=api | Q20: https://cards.scryfall.io/normal/front/3/0/302f0dc1-88ab-4961-b78c-fbe7980dca18.jpg?1783908083 | R20: Heonhwa | S20: Nein | T20: Ja | U20: Ja
A21: Serra Paragon | B21: {2}{W}{W} | C21: 4 | D21: Creature — Angel | E21: Kreatur | F21: legal | G21: W | H21: 3 | I21: 4 | K21: Flying Once during each of your turns, you may play a land from your graveyard or cast a permanent spell with mana value 3 or less from your graveyard. If you do, it gains "When this permanent is put into a graveyard from the battlefield, exile it and you gain 2 life." | L21: SOC | M21: 169 | N21: 2026-04-24 | P21: https://scryfall.com/card/soc/169/serra-paragon?utm_source=api | Q21: https://cards.scryfall.io/normal/front/8/e/8e77a410-a053-4349-950c-d59e76b17923.jpg?1783903802 | R21: Heonhwa | S21: Nein | T21: Ja | U21: Ja
A22: Adeline, Resplendent Cathar | B22: {1}{W}{W} | C22: 3 | D22: Legendary Creature — Human Knight | E22: Kreatur | F22: legal | G22: W | H22: * | I22: 4 | K22: Vigilance Adeline's power is equal to the number of creatures you control. Whenever you attack, for each opponent, create a 1/1 white Human creature token that's tapped and attacking that player or a planeswalker they control. | L22: TDC | M22: 108 | N22: 2025-04-11 | P22: https://scryfall.com/card/tdc/108/adeline-resplendent-cathar?utm_source=api | Q22: https://cards.scryfall.io/normal/front/1/d/1de30c12-2011-495a-be25-f7a46b23e142.jpg?1783907131 | R22: Bryan Sola | S22: Nein | T22: Ja | U22: Ja
A23: Queen Marchesa | B23: {1}{R}{W}{B} | C23: 4 | D23: Legendary Creature — Human Assassin | E23: Kreatur | F23: legal | G23: BRW | H23: 3 | I23: 3 | K23: Deathtouch, haste When Queen Marchesa enters, you become the monarch. At the beginning of your upkeep, if an opponent is the monarch, create a 1/1 black Assassin creature token with deathtouch and haste. | L23: OTC | M23: 239 | N23: 2024-04-19 | P23: https://scryfall.com/card/otc/239/queen-marchesa?utm_source=api | Q23: https://cards.scryfall.io/normal/front/0/f/0fdae05f-7bdc-45fb-b9b9-e5ec3766f965.jpg?1783911896 | R23: Kieran Yanner | S23: Nein | T23: Ja | U23: Ja
A24: Kraum, Ludevic's Opus | B24: {3}{U}{R} | C24: 5 | D24: Legendary Creature — Zombie Horror | E24: Kreatur | F24: legal | G24: RU | H24: 4 | I24: 4 | K24: Flying, haste Whenever an opponent casts their second spell each turn, draw a card. Partner (You can have two commanders if both have partner.) | L24: C16 | M24: 34 | N24: 2016-11-11 | P24: https://scryfall.com/card/c16/34/kraum-ludevics-opus?utm_source=api | Q24: https://cards.scryfall.io/normal/front/5/5/557fcd17-6cb3-414a-b2b1-ea9ae32e5aec.jpg?1783937084 | R24: Aaron Miller | S24: Nein | T24: Ja | U24: Ja
A25: Toxrill, the Corrosive | B25: {5}{B}{B} | C25: 7 | D25: Legendary Creature — Slug Horror | E25: Kreatur | F25: legal | G25: BU | H25: 7 | I25: 7 | K25: At the beginning of each end step, put a slime counter on each creature you don't control. Creatures you don't control get -1/-1 for each slime counter on them. Whenever a creature you don't control with a slime counter on it dies, create a 1/1 black Slug creature token. {U}{B}, Sacrifice a Slug: Draw a card. | L25: VOW | M25: 132 | N25: 2021-11-19 | P25: https://scryfall.com/card/vow/132/toxrill-the-corrosive?utm_source=api | Q25: https://cards.scryfall.io/normal/front/8/4/84e64f38-b1f3-47cd-8cfb-a4861369aca3.jpg?1783924850 | R25: Simon Dominic | S25: Nein | T25: Ja | U25: Ja
A26: Nemata, Primeval Warden | B26: {2}{B}{G} | C26: 4 | D26: Legendary Creature — Treefolk | E26: Kreatur | F26: legal | G26: BG | H26: 3 | I26: 4 | K26: Reach If a creature an opponent controls would die, exile it instead. When you do, create a 1/1 green Saproling creature token. {G}, Sacrifice a Saproling: Nemata gets +2/+2 until end of turn. {1}{B}, Sacrifice two Saprolings: Draw a card. | L26: DMU | M26: 209 | N26: 2022-09-09 | P26: https://scryfall.com/card/dmu/209/nemata-primeval-warden?utm_source=api | Q26: https://cards.scryfall.io/normal/front/a/d/adcd556d-351f-4faf-9456-0e47def69a69.jpg?1783921281 | R26: Andrew Mar | S26: Nein | T26: Ja | U26: Ja
A27: Toralf, God of Fury | B27: {2}{R}{R} // {1}{R} | C27: 4 | D27: Legendary Creature — God // Legendary Artifact — Equipment | E27: Kreatur | F27: legal | G27: R | H27: 5 | I27: 4 | K27: Trample Whenever a creature or planeswalker an opponent controls is dealt excess noncombat damage, Toralf deals damage equal to the excess to any target other than that permanent. // Equipped creature has "{1}{R}, {T}, Unattach Toralf's Hammer: It deals 3 damage to any target. Return Toralf's Hammer to its owner's hand." Equipped creature gets +3/+0 as long as it's legendary. Equip {1}{R} | L27: KHM | M27: 154 | N27: 2021-02-05 | P27: https://scryfall.com/card/khm/154/toralf-god-of-fury-toralfs-hammer?utm_source=api | Q27: https://cards.scryfall.io/normal/front/2/2/22a6a5f1-1405-4efb-af3e-e1f58d664e99.jpg?1783928227 | R27: Tyler Jacobson | S27: Nein | T27: Ja | U27: Ja
A28: Heliod, Sun-Crowned | B28: {2}{W} | C28: 3 | D28: Legendary Enchantment Creature — God | E28: Kreatur | F28: legal | G28: W | H28: 5 | I28: 5 | K28: Indestructible As long as your devotion to white is less than five, Heliod isn't a creature. Whenever you gain life, put a +1/+1 counter on target creature or enchantment you control. {1}{W}: Another target creature gains lifelink until end of turn. | L28: CMM | M28: 29 | N28: 2023-08-04 | P28: https://scryfall.com/card/cmm/29/heliod-sun-crowned?utm_source=api | Q28: https://cards.scryfall.io/normal/front/3/2/3245ff74-1f9c-4518-a23f-1579f338f232.jpg?1783915722 | R28: Lius Lasahido | S28: Nein | T28: Ja | U28: Ja
A29: Krenko, Mob Boss | B29: {2}{R}{R} | C29: 4 | D29: Legendary Creature — Goblin Warrior | E29: Kreatur | F29: legal | G29: R | H29: 3 | I29: 3 | K29: {T}: Create X 1/1 red Goblin creature tokens, where X is the number of Goblins you control. | L29: FDN | M29: 204 | N29: 2024-11-15 | P29: https://scryfall.com/card/fdn/204/krenko-mob-boss?utm_source=api | Q29: https://cards.scryfall.io/normal/front/8/2/824b2d73-2151-4e5e-9f05-8f63e2bdcaa9.jpg?1783909065 | R29: Lie Setiawan | S29: Nein | T29: Ja | U29: Ja
A30: Xanathar, Guild Kingpin | B30: {4}{U}{B} | C30: 6 | D30: Legendary Creature — Beholder | E30: Kreatur | F30: legal | G30: BU | H30: 5 | I30: 6 | K30: At the beginning of your upkeep, choose target opponent. Until end of turn, that player can't cast spells, you may look at the top card of their library any time, you may play the top card of their library, and you may spend mana as though it were mana of any color to cast spells this way. | L30: AFR | M30: 239 | N30: 2021-07-23 | P30: https://scryfall.com/card/afr/239/xanathar-guild-kingpin?utm_source=api | Q30: https://cards.scryfall.io/normal/front/5/b/5bc58050-a615-4090-9cf5-cd49ccb4e2c6.jpg?1783926441 | R30: Kieran Yanner | S30: Nein | T30: Ja | U30: Ja
A31: Surrak Dragonclaw | B31: {2}{G}{U}{R} | C31: 5 | D31: Legendary Creature — Human Warrior | E31: Kreatur | F31: legal | G31: GRU | H31: 6 | I31: 6 | K31: Flash This spell can't be countered. Creature spells you control can't be countered. Other creatures you control have trample. | L31: DMC | M31: 169 | N31: 2022-09-09 | P31: https://scryfall.com/card/dmc/169/surrak-dragonclaw?utm_source=api | Q31: https://cards.scryfall.io/normal/front/e/8/e8efe72d-3c01-4dd6-b3dd-0382ac09dc52.jpg?1783921404 | R31: Jaime Jones | S31: Nein | T31: Ja | U31: Ja
A32: Faramir, Steward of Gondor | B32: {1}{W}{U} | C32: 3 | D32: Legendary Creature — Human Noble | E32: Kreatur | F32: legal | G32: UW | H32: 2 | I32: 2 | K32: Whenever a legendary creature you control with mana value 4 or greater enters, you become the monarch. At the beginning of your end step, if you're the monarch, create two 1/1 white Human Soldier creature tokens. | L32: LTC | M32: 54 | N32: 2023-06-23 | P32: https://scryfall.com/card/ltc/54/faramir-steward-of-gondor?utm_source=api | Q32: https://cards.scryfall.io/normal/front/5/c/5c3e8a30-de2a-4d8f-a929-5abeaea2e65a.jpg?1783916020 | R32: Anna Podedworna | S32: Nein | T32: Ja | U32: Ja
A33: Blasphemous Act | B33: {8}{R} | C33: 9 | D33: Sorcery | E33: Hexerei | F33: legal | G33: R | K33: This spell costs {1} less to cast for each creature on the battlefield. Blasphemous Act deals 13 damage to each creature. | L33: MSC | M33: 163 | N33: 2026-06-26 | P33: https://scryfall.com/card/msc/163/blasphemous-act?utm_source=api | Q33: https://cards.scryfall.io/normal/front/7/d/7d4b1d44-126e-4987-9a9f-f0f9627a09cb.jpg?1783903234 | R33: Immanuela Crovius | S33: Nein | T33: Ja | U33: Ja
A34: Mystic Remora | B34: {U} | C34: 1 | D34: Enchantment | E34: Verzauberung | F34: legal | G34: U | K34: Cumulative upkeep {1} (At the beginning of your upkeep, put an age counter on this permanent, then sacrifice it unless you pay its upkeep cost for each age counter on it.) Whenever an opponent casts a noncreature spell, you may draw a card unless that player pays {4}. | L34: DMR | M34: 59 | N34: 2023-01-13 | O34: 8a52f3c0-2552-4425-b2e3-5496eb2232a7 | P34: https://scryfall.com/card/dmr/59/mystic-remora?utm_source=api | Q34: https://cards.scryfall.io/normal/front/4/0/40140991-cffa-4b52-9a25-37e9a8aa9ddd.jpg?1783918491 | R34: Jesper Ejsing | S34: Nein | T34: Ja | U34: Ja
A35: Rancor | B35: {G} | C35: 1 | D35: Enchantment — Aura | E35: Verzauberung | F35: legal | G35: G | K35: Enchant creature Enchanted creature gets +2/+0 and has trample. When this Aura is put into a graveyard from the battlefield, return it to its owner's hand. | L35: 2X2 | M35: 156 | N35: 2022-07-08 | O35: 9d2d6479-531c-4ce1-b52b-00e36fa63b64 | P35: https://scryfall.com/card/2x2/156/rancor?utm_source=api | Q35: https://cards.scryfall.io/normal/front/8/6/86d6b411-4a31-4bfc-8dd6-e19f553bb29b.jpg?1783921864 | R35: Kev Walker | S35: Nein | T35: Ja | U35: Ja
A36: Bloom Tender | B36: {1}{G} | C36: 2 | D36: Creature — Elf Druid | E36: Kreatur | F36: legal | G36: G | H36: 1 | I36: 1 | K36: Vivid — {T}: For each color among permanents you control, add one mana of that color. | L36: ECL | M36: 166 | N36: 2026-01-23 | O36: 0c23fefe-9891-4dd8-9bb1-eebdb3274e31 | P36: https://scryfall.com/card/ecl/166/bloom-tender?utm_source=api | Q36: https://cards.scryfall.io/normal/front/b/a/ba86688d-18f0-4b5c-a797-42bf125a6c9f.jpg?1783904436 | R36: Nils Hamm | S36: Nein | T36: Ja | U36: Ja
A37: Kodama's Reach | B37: {2}{G} | C37: 3 | D37: Sorcery — Arcane | E37: Hexerei | F37: legal | G37: G | K37: Search your library for up to two basic land cards, reveal those cards, put one onto the battlefield tapped and the other into your hand, then shuffle. | L37: ECC | M37: 113 | N37: 2026-01-23 | O37: 1593ea18-2f2f-4ab4-83fb-6ccc0bec8a90 | P37: https://scryfall.com/card/ecc/113/kodamas-reach?utm_source=api | Q37: https://cards.scryfall.io/normal/front/9/0/90c423cc-1264-4067-9c50-e7c88c68ef2d.jpg?1783904544 | R37: John Avon | S37: Nein | T37: Ja | U37: Ja
A38: Rhystic Study | B38: {2}{U} | C38: 3 | D38: Enchantment | E38: Verzauberung | F38: legal | G38: U | K38: Whenever an opponent casts a spell, you may draw a card unless that player pays {1}. | L38: J22 | M38: 114 | N38: 2022-12-02 | O38: 53236dd7-845a-444c-96d5-f41ed7325d8f | P38: https://scryfall.com/card/j22/114/rhystic-study?utm_source=api | Q38: https://cards.scryfall.io/normal/front/9/f/9f37c5b6-a59c-45cd-9a99-e9357fe9ea1b.jpg?1783919146 | R38: Tatiana Kirgetova | S38: Nein | T38: Ja | U38: Ja
A39: Balefire Dragon | B39: {5}{R}{R} | C39: 7 | D39: Creature — Dragon | E39: Kreatur | F39: legal | G39: R | H39: 6 | I39: 6 | K39: Flying Whenever this creature deals combat damage to a player, it deals that much damage to each creature that player controls. | L39: INR | M39: 479 | N39: 2025-01-24 | O39: 3d783beb-9ca6-4681-9276-fc3ad13b993f | P39: https://scryfall.com/card/inr/479/balefire-dragon?utm_source=api | Q39: https://cards.scryfall.io/normal/front/e/4/e4510ee2-8a2e-4fe5-94af-df420a6a35a0.jpg?1783907975 | R39: Eric Deschamps | S39: Nein | T39: Ja | U39: Ja
A40: Toxic Deluge | B40: {2}{B} | C40: 3 | D40: Sorcery | E40: Hexerei | F40: legal | G40: B | K40: As an additional cost to cast this spell, pay X life. All creatures get -X/-X until end of turn. | L40: MSC | M40: 161 | N40: 2026-06-26 | P40: https://scryfall.com/card/msc/161/toxic-deluge?utm_source=api | Q40: https://cards.scryfall.io/normal/front/d/e/de5afccc-8d42-4bd6-b068-b9ea2361655e.jpg?1783903236 | R40: Anthony Devine | S40: Nein | T40: Ja | U40: Ja
A41: Chromatic Lantern | B41: {3} | C41: 3 | D41: Artifact | E41: Artefakt | F41: legal | G41: — | K41: Lands you control have "{T}: Add one mana of any color." {T}: Add one mana of any color. | L41: RTR | M41: 226 | N41: 2012-10-05 | P41: https://scryfall.com/card/rtr/226/chromatic-lantern?utm_source=api | Q41: https://cards.scryfall.io/normal/front/5/7/57f4e0f0-13d1-43ed-8d95-13cff94a26e7.jpg?1783940325 | R41: Jung Park | S41: Nein | T41: Ja | U41: Ja
A42: Anguished Unmaking | B42: {1}{W}{B} | C42: 3 | D42: Instant | E42: Spontanzauber | F42: legal | G42: BW | K42: Exile target nonland permanent. You lose 3 life. | L42: SOC | M42: 293 | N42: 2026-04-24 | P42: https://scryfall.com/card/soc/293/anguished-unmaking?utm_source=api | Q42: https://cards.scryfall.io/normal/front/4/0/407183c6-c962-4f8c-867e-abc309b6c573.jpg?1783903759 | R42: Wesley Burt | S42: Nein | T42: Ja | U42: Ja
A43: Garruk's Uprising | B43: {2}{G} | C43: 3 | D43: Enchantment | E43: Verzauberung | F43: legal | G43: G | K43: When this enchantment enters, if you control a creature with power 4 or greater, draw a card. Creatures you control have trample. (Each of those creatures can deal excess combat damage to the player or planeswalker it's attacking.) Whenever a creature you control with power 4 or greater enters, draw a card. | L43: ECC | M43: 109 | N43: 2026-01-23 | O43: 3127ae9b-a7a7-43ec-89d7-688f8445b33d | P43: https://scryfall.com/card/ecc/109/garruks-uprising?utm_source=api | Q43: https://cards.scryfall.io/normal/front/b/5/b58c4033-f764-42f6-966f-b7202a2babbf.jpg?1783904546 | R43: Wisnu Tan | S43: Nein | T43: Ja | U43: Ja
...

Sheet Spielplan
A1: Spielplan · so funktioniert der Heldenbund
A2: Vom Start bis zum Kampfsieg – mit den relevanten Esika-Interaktionen und einem verbindlichen Gestaltungsrahmen.
